Workbook

Sheet Invoice Bag. Umum
A1: PT. BiAS SURYA TEKNOLOGI | D1: Inv No. : | E1: INV25-R-296
D2: Date : | E2: 46007
A3: Greenland Housing Blok E6 No. 11 | D3: Kepada Yth.
A4: Batam Kota - Batam - Kepulauan Riau | D4: Bagian Umum Setdako Batam
A5: Telp : +62 811 7045 657 | D5: Jl. Engku Putri No. 1 Tlk. Tering
A6: Email : admin@biasbst.com | D6: Kec. Batam Kota Kota Batam
A7: www.biasbst.com | D7: PIC. Bapak Firdaus - 0853 76200022
A8: INVOICE
A9: Periode : December 2025
A10: No | B10: Description | E10: Amount
A11: 1 | B11: Rental Charges Ruangan Bag. Umum Epson Workforce Pro WF-C878R | E11: 2500000
B12: Colour Inject (X6G001409) 1 Unit
B13: B/W
B14: Start Meter Reading | C14: ='Meterading 2025'!B17 -> 89982
B15: Last Meter Reading | C15: ='Meterading 2025'!C17 -> 90826 | D15: (-)
B16: Total Copies | C16: =+C15-C14 -> 844
B17: Colour
B18: Start Meter Reading | C18: ='Meterading 2025'!F17 -> 31764
B19: Last Meter Reading | C19: ='Meterading 2025'!G17 -> 32280 | D19: (-)
B20: Total Copies | C20: =+C19-C18 -> 516
B21: Free Copies | C21: 200 | D21: (-)
B22: Total Copies | C22: =+C20-C21 -> 316
A24: 2 | B24: Copies Charges B/W | C24: (x) | D24: 150 | E24: =C16*D24 -> 126600
A25: 3 | B25: Copies Charges Colour | C25: (x) | D25: 1300 | E25: =D25*C22 -> 410800
D26: TOTAL | E26: =E11+E24+E25 -> 3037400
A27: Pembayaran Transfer ke rekening : | D27: TAX | E27: 0
A28: PT. BIAS SURYA TEKNOLOGI | D28: TOTAL PAY | E28: =+E26 -> 3037400
A29: NPWP : 0941.8395.0822.5000
A30: BANK RIAU KEPRI SYARIAH CAB. BATAM
A31: Rek No. 1060885757
A32: BANK MANDIRI CABANG BATAM
A33: Rek No. 109-00-3388575-7
G34: `
A35: Received By, | C35: PT. BiAS SURYA TEKNOLOGI
A39: _______________________ | C39: Grace Hutapea
D40: Admin Finance
A42: PT. BiAS SURYA TEKNOLOGI | D42: Inv No. : | E42: INV25-R-291
D43: Date : | E43: 45992
A44: Greenland Housing Blok E6 No. 11 | D44: Kepada Yth.
A45: Batam Kota - Batam - Kepulauan Riau | D45: Bagian Umum Setdako Batam
...

Sheet Invoice Setdako
A1: PT. BiAS SURYA TEKNOLOGI | D1: Inv No. : | E1: INV25-R-297
D2: Date : | E2: 46007
A3: Greenland Housing Blok E6 No. 11 | D3: Kepada Yth.
A4: Batam Kota - Batam - Kepulauan Riau | D4: Bagian Umum Setdako Batam
A5: Telp : +62 811 7045 657 | D5: Jl. Engku Putri No. 1 Tlk. Tering
A6: Email : admin@biasbst.com | D6: Kec. Batam Kota Kota Batam
A7: www.biasbst.com | D7: PIC. Bapak Firdaus - 0853 76200022
A9: INVOICE
A10: Periode : December 2025
A11: No | B11: Description | E11: Amount
A12: 1 | B12: Rental Charges Ruangan Setdako Mesin Epson Workforce Pro WF-C878R | E12: 2500000
B13: Colour Inject (X6G001418) 1 Unit
B14: B/W
B15: New Meter Reading | C15: ='Meterading 2025'!B36 -> 76876
B16: Last Meter Reading | C16: ='Meterading 2025'!C36 -> 77782 | D16: (-)
B17: Total Copies | C17: =+C16-C15 -> 906
B18: Colour
B19: New Meter Reading | C19: ='Meterading 2025'!F36 -> 12943
B20: Last Meter Reading | C20: ='Meterading 2025'!G36 -> 13475 | D20: (-)
B21: Total Copies | C21: =+C20-C19 -> 532
B22: Free Copies | C22: 200 | D22: (-)
B23: Total Copies | C23: =+C21-C22 -> 332
A25: 2 | B25: Copies Charges B/W | C25: (x) | D25: 150 | E25: =C17*D25 -> 135900
A26: 3 | B26: Copies Charges Colour | C26: (x) | D26: 1300 | E26: =+C23*D26 -> 431600
D27: TOTAL | E27: =+E26+E25+E12 -> 3067500
A28: Pembayaran Transfer ke rekening : | D28: TAX | E28: 0
A29: PT. BIAS SURYA TEKNOLOGI | D29: TOTAL PAY | E29: =(E27+E28) -> 3067500
A30: NPWP : 0941.8395.0822.5000
A31: BANK RIAU KEPRI SYARIAH CAB. BATAM
A32: Rek No. 1060885757
A33: BANK MANDIRI CABANG BATAM
A34: Rek No. 109-00-3388575-7
A36: Received By, | C36: PT. BiAS SURYA TEKNOLOGI
A40: _______________________ | C40: Grace Hutapea
D41: Admin Finance
A43: PT. BiAS SURYA TEKNOLOGI | D43: Inv No. : | E43: INV25-R-292
D44: Date : | E44: 45992
A45: Greenland Housing Blok E6 No. 11 | D45: Kepada Yth.
A46: Batam Kota - Batam - Kepulauan Riau | D46: Bagian Umum Setdako Batam
A47: Telp : +62 811 7045 657 | D47: Jl. Engku Putri No. 1 Tlk. Tering
...

Sheet INVOICE RENTAL PT. BARELANG RIA
A1: PT. BiAS SURYA TEKNOLOGI | D1: Inv No. : | E1: INV26-R-298
D2: Date : | E2: 46024
A3: Greenland Housing Blok E6 No. 11 | D3: Kepada Yth.
A4: Batam Kota - Batam - Kepulauan Riau | D4: PT. BARELANG RIAU JAYA
A5: Telp : +62 811 7045 657 | D5: Kompleks Union Industrial Park Blok G no 7
A6: Email : admin@biasbst.com | D6: Jl.Yos Sudarso-Batu Ampar- Batam
A7: www.biasbst.com | D7: PIC. Bapak Halim - +62 813-7219-0091
A10: INVOICE
A12: Periode : December 2025
A13: No | B13: Description | E13: Amount
A14: 1 | B14: Rental Charges Mesin Kyocera Ecosys M2640 idw (VY91603662) 1 Unit | E14: 800000
B15: New Meter Reading | C15: ='Meterading 2025'!B54 -> 105982
B16: Last Meter Reading | C16: ='Meterading 2025'!C54 -> 107840 | D16: (-) | K16: ,
B17: Total Copies | C17: =C16-C15 -> 1858
B18: Free Copies | C18: 2000 | D18: (-)
B19: Total Copies | C19: 0
A20: 2 | B20: Copies Charges B/W | C20: (x) | D20: 90 | E20: =C19*D20 -> 0
D21: TOTAL | E21: =E14+E20 -> 800000
A22: Pembayaran Transfer ke rekening : | D22: TAX | E22: 0
A23: BANK MANDIRI CABANG BATAM | D23: TOTAL PAY | E23: =(E21+E22) -> 800000
A24: Rek No. 109-00-3388575-7
A25: A/N : PT. BIAS SURYA TEKNOLOGI
A26: NPWP : 0941.8395.0822.5000
A28: Received By, | C28: PT. BiAS SURYA TEKNOLOGI
A32: _______________________ | C32: Grace Hutapea
D33: Admin Finance
A35: PT. BiAS SURYA TEKNOLOGI | D35: Inv No. : | E35: INV25-R-293
D36: Date : | E36: 45992
A37: Greenland Housing Blok E6 No. 11 | D37: Kepada Yth.
A38: Batam Kota - Batam - Kepulauan Riau | D38: PT. BARELANG RIAU JAYA
A39: Telp : +62 811 7045 657 | D39: Kompleks Union Industrial Park Blok G no 7
A40: Email : admin@biasbst.com | D40: Jl.Yos Sudarso-Batu Ampar- Batam
A41: www.biasbst.com | D41: PIC. Bapak Halim - +62 813-7219-0091
A44: INVOICE
A46: Periode : November 2025
A47: No | B47: Description | E47: Amount
A48: 1 | B48: Rental Charges Mesin Kyocera Ecosys M2640 idw (VY91603662) 1 Unit | E48: 800000
B49: New Meter Reading | C49: ='Meterading 2025'!B53 -> 104492
B50: Last Meter Reading | C50: ='Meterading 2025'!C53 -> 105982 | D50: (-) | K50: ,
B51: Total Copies | C51: =C50-C49 -> 1490
...

Sheet Invoice Atlas Copco
A1: PT. BiAS SURYA TEKNOLOGI | D1: Inv No. : | E1: INV25-R-299
D2: Date : | E2: 46031
A3: Greenland Housing Blok E6 No. 11 | D3: Kepada Yth.
A4: Batam Kota - Batam - Kepulauan Riau | D4: PT Elang Mandiri Solusi
A5: Telp : +62 811 7045 657 | D5: Pusat Niaga Roxy Mas, Jl. Kh Hasyim Ashari No.9-12, RW.8, Cideng, Kecamatan Gambir, Kota Jakarta Pusat, Daerah Khusus Ibukota Jakarta 10150
A6: Email : admin@biasbst.com
A7: www.biasbst.com | D7: Up | E7: Finance
A9: INVOICE
A10: Periode : December 2025
A11: No | B11: Description | E11: Amount
A12: 1 | B12: Rental Charges Mesin Fotocopy PT. Atlas Copco Indonesia Batam | E12: 2000000
B13: Epson WF-C878R S/N : X6GD002742 1 Unit
B14: B/W A4
B15: Start Meter Reading | C15: ='Meterading 2025'!B74 -> 13444
B16: Last Meter Reading | C16: ='Meterading 2025'!C74 -> 13616 | D16: (-)
B17: Total Copies | C17: =C16-C15 -> 172
B18: Free Copies | C18: 3000 | D18: (-)
B19: Total Copies | C19: =C17-C18 -> -2828
B20: Colour A4
B21: Start Meter Reading | C21: ='Meterading 2025'!F74 -> 13027
B22: Last Meter Reading | C22: ='Meterading 2025'!G74 -> 13286 | D22: (-)
B23: Total Copies | C23: =C22-C21 -> 259
B24: Free Copies | C24: 100 | D24: (-)
B25: Total Copies | C25: =+C23-C24 -> 159
B26: B/W A3
B27: Start Meter Reading | C27: 6
B28: Last Meter Reading | C28: 6 | D28: (-)
B29: Total Copies | C29: =+C28-C27 -> 0
B30: Free Copies | C30: 0 | D30: (-)
B31: Total Copies | C31: 0
B32: Colour A3
B33: Start Meter Reading | C33: 11
B34: Last Meter Reading | C34: 11 | D34: (-)
B35: Total Copies | C35: =+C34-C33 -> 0
A36: 2 | B36: Copies Charges B/W A4 | C36: (x) | D36: 110 | E36: 0
A37: 3 | B37: Copies Charges Colour A4 | C37: (x) | D37: 1100 | E37: =C25*D37 -> 174900
A38: 4 | B38: Copies Charges B/W A3 | C38: (x) | D38: 150 | E38: 0
A39: 5 | B39: Copies Charges Colour A3 | C39: (x) | D39: 1650 | E39: =+D39*C35 -> 0
D40: TOTAL | E40: =+E12+E36+E37+E38+E39 -> 2174900
A41: Pembayaran Transfer ke rekening : | D41: TAX
...

Sheet Great Eastern General Insura
A1: PT. BiAS SURYA TEKNOLOGI | D1: Inv No. : | E1: INV25-R-300
D2: Date : | E2: 46031
A3: Greenland Housing Blok E6 No. 11 | D3: Kepada Yth.
A4: Batam Kota - Batam - Kepulauan Riau | D4: PT Elang Mandiri Solusi
A5: Telp : +62 811 7045 657 | D5: Pusat Niaga Roxy Mas, Jl. Kh Hasyim Ashari No.9-12, RW.8, Cideng, Kecamatan Gambir, Kota Jakarta Pusat, Daerah Khusus Ibukota Jakarta 10150 | H5: contoh perhitungannya ya bu
A6: Email : admin@biasbst.com
A7: www.biasbst.com | D7: Up | E7: Finance
H8: COUNTER AWAL | I8: COUNTER AKHIR | J8: PEMAKAIAN
A9: INVOICE | G9: BW | H9: 15172 | I9: 11835 | J9: =H9-I9 -> 3337
A10: Periode : December 2025 | G10: CPLOUR | H10: 11023 | I10: 15172 | J10: =I10-H10 -> 4149
A11: No | B11: Description | E11: Amount
A12: 1 | B12: Rental Charges Mesin Fotocopy Great Eastern General Insurance Batam | E12: 2000000
B13: Epson WorkForce Enterprise AM-C550 S/N : XBB9000164 1 Unit
B14: B/W A4 | G14: BW | H14: =J10 -> 4149 | I14: x | J14: 0.88 | K14: = | L14: =J14*H14 -> 3651.12 | M14: + | N14: =J9 -> 3337 | O14: =L14+N14 -> 6988.12
B15: Start Meter Reading | C15: 11835 | G15: CL | H15: =H14 -> 4149 | I15: x | J15: 0.12 | K15: = | L15: =J15*H15 -> 497.88
B16: Last Meter Reading | C16: 15172 | D16: (-)
B17: Total Copies | C17: =+C16-C15 -> 3337
B18: Free Copies | C18: 11539 | D18: (-)
B19: Total Copies | C19: =C17-C18 -> -8202
B20: Colour A4
B21: Start Meter Reading | C21: 498
B22: Last Meter Reading | C22: 259 | D22: (-)
B23: Total Copies | C23: =+C22-C21 -> -239
B24: Free Copies | C24: 462 | D24: (-)
B25: Total Copies | C25: =+C23-C24 -> -701
A26: 2 | B26: Copies Charges B/W A4 | C26: (x) | D26: 100 | E26: 0
A27: 3 | B27: Copies Charges Colour A4 | C27: (x) | D27: 1000 | E27: 0
D28: TOTAL | E28: =E12+E27+E26 -> 2000000
D29: D.P.P
A30: Pembayaran Transfer ke rekening : | D30: PPN
A31: PT. BIAS SURYA TEKNOLOGI | D31: TOTAL PAY | E31: =+E28+E30 -> 2000000
A32: NPWP : 94.183.950.8.225.000
A33: BANK RIAU KEPRI SYARIAH CAB. BATAM
A34: Rek No. 1060885757
A35: BANK MANDIRI CABANG BATAM
A36: Rek No. 109-00-3388575-7
A39: Received By, | C39: PT. BiAS SURYA TEKNOLOGI
A43: _______________________ | C43: Grace Hutapea
D44: Admin Finance
A46: PT. BiAS SURYA TEKNOLOGI | D46: Inv No. : | E46: INV25-R-295
...

Sheet Meterading 2025
A1: Meterading 2025
A2: Rental Charges Ruangan Bag. Umum Epson Workforce Pro WF-C878R Colour Inject (X6G001409) 1 Unit
A4: Month | B4: B/W | D4: Used | E4: Remarks | F4: COLOUR | H4: Used
B5: START | C5: LAST | F5: START | G5: LAST
A6: January | B6: 70439 | C6: 73632 | D6: =C6-B6 -> 3193 | F6: 20408 | G6: 21884 | H6: =G6-F6 -> 1476
A7: February | B7: =+C6 -> 73632 | C7: 75461 | D7: =C7-B7 -> 1829 | F7: =+G6 -> 21884 | G7: 22564 | H7: =G7-F7 -> 680
A8: March | B8: =+C7 -> 75461 | C8: 77475 | D8: =C8-B8 -> 2014 | F8: =+G7 -> 22564 | G8: 23344 | H8: =G8-F8 -> 780
A9: April | B9: =+C8 -> 77475 | C9: 78332 | D9: =C9-B9 -> 857 | F9: =+G8 -> 23344 | G9: 24132 | H9: =G9-F9 -> 788
A10: May | B10: =C9 -> 78332 | C10: 81259 | D10: =C10-B10 -> 2927 | F10: =G9 -> 24132 | G10: 25796 | H10: =G10-F10 -> 1664
A11: June | B11: =C10 -> 81259 | C11: 83203 | D11: =C11-B11 -> 1944 | F11: =G10 -> 25796 | G11: 27398 | H11: =G11-F11 -> 1602
A12: July | B12: =C11 -> 83203 | C12: 84968 | D12: =C12-B12 -> 1765 | F12: =G11 -> 27398 | G12: 28650 | H12: =G12-F12 -> 1252
A13: August | B13: =C12 -> 84968 | C13: 85849 | D13: =C13-B13 -> 881 | F13: =G12 -> 28650 | G13: 29295 | H13: =G13-F13 -> 645
A14: September | B14: =C13 -> 85849 | C14: 87477 | D14: =C14-B14 -> 1628 | F14: =G13 -> 29295 | G14: 30426 | H14: =G14-F14 -> 1131
A15: October | B15: =C14 -> 87477 | C15: 88654 | D15: =C15-B15 -> 1177 | F15: =G14 -> 30426 | G15: 31254 | H15: =G15-F15 -> 828
A16: November | B16: =C15 -> 88654 | C16: 89982 | D16: =C16-B16 -> 1328 | F16: =G15 -> 31254 | G16: 31764 | H16: =G16-F16 -> 510
A17: December | B17: =C16 -> 89982 | C17: 90826 | D17: =C17-B17 -> 844 | F17: =G16 -> 31764 | G17: 32280 | H17: =G17-F17 -> 516
A20: Meterading 2025
A21: Rental Charges Ruangan Setdako Mesin Epson Workforce Pro WF-C878R Colour Inject (X6G001418) 1 Unit
A23: Month | B23: B/W | D23: Used | E23: Remarks | F23: COLOUR | H23: Used
B24: START | C24: LAST | F24: START | G24: LAST
A25: January | B25: 63270 | C25: 64828 | D25: =C25-B25 -> 1558 | F25: 4863 | G25: 5973 | H25: =G25-F25 -> 1110
A26: February | B26: =+C25 -> 64828 | C26: 66187 | D26: =C26-B26 -> 1359 | F26: =+G25 -> 5973 | G26: 6409 | H26: =G26-F26 -> 436
A27: March | B27: =+C26 -> 66187 | C27: 67013 | D27: =C27-B27 -> 826 | F27: =+G26 -> 6409 | G27: 7127 | H27: =G27-F27 -> 718
A28: April | B28: =+C27 -> 67013 | C28: 68217 | D28: =C28-B28 -> 1204 | F28: =+G27 -> 7127 | G28: 7886 | H28: =G28-F28 -> 759
A29: May | B29: =C28 -> 68217 | C29: 69441 | D29: =C29-B29 -> 1224 | F29: =G28 -> 7886 | G29: 9225 | H29: =G29-F29 -> 1339
A30: June | B30: =C29 -> 69441 | C30: 70711 | D30: =C30-B30 -> 1270 | F30: =G29 -> 9225 | G30: 9677 | H30: =G30-F30 -> 452
A31: July | B31: =C30 -> 70711 | C31: 71953 | D31: =C31-B31 -> 1242 | F31: =G30 -> 9677 | G31: 10290 | H31: =G31-F31 -> 613
A32: August | B32: =C31 -> 71953 | C32: 73159 | D32: =C32-B32 -> 1206 | F32: =G31 -> 10290 | G32: 10736 | H32: =G32-F32 -> 446
A33: September | B33: =C32 -> 73159 | C33: 74511 | D33: =C33-B33 -> 1352 | F33: =G32 -> 10736 | G33: 11343 | H33: =G33-F33 -> 607
A34: October | B34: =C33 -> 74511 | C34: 75838 | D34: =C34-B34 -> 1327 | F34: =G33 -> 11343 | G34: 12214 | H34: =G34-F34 -> 871
A35: November | B35: =C34 -> 75838 | C35: 76876 | D35: =C35-B35 -> 1038 | F35: =G34 -> 12214 | G35: 12943 | H35: =G35-F35 -> 729
A36: December | B36: =C35 -> 76876 | C36: 77782 | D36: =C36-B36 -> 906 | F36: =G35 -> 12943 | G36: 13475 | H36: =G36-F36 -> 532
A38: Meterading 2025
A39: Rental Charges Mesin Kyocera Ecosys M2640 idw (VY91603662) 1 Unit Barelang Riau Jaya
A41: Month | B41: B/W | D41: Used | E41: Remarks
B42: START | C42: LAST
A43: January | B43: 88977 | C43: 89767 | D43: =C43-B43 -> 790
A44: February | B44: 88977 | C44: 90753 | D44: =C44-B44 -> 1776
A45: March | B45: =+C44 -> 90753 | C45: 92685 | D45: =C45-B45 -> 1932
A46: April | B46: =C45 -> 92685 | C46: 94657 | D46: =C46-B46 -> 1972
...
